2025-09-29 10:00:19,276 - TeleBot - ERROR - Infinity polling: polling exited
2025-09-29 10:00:19,294 - TeleBot - ERROR - Break infinity polling
2025-09-29 10:00:19,299 - __main__ - ERROR - Ошибка в polling: object NoneType can't be used in 'await' expression
2025-09-29 10:18:22,743 - TeleBot - ERROR - Threaded polling exception: A request to the Telegram API was unsuccessful. Error code: 400. Description: Bad Request: can't parse entities: Unsupported start tag "описание" at byte offset 293
2025-09-29 10:18:22,765 - TeleBot - ERROR - Exception traceback:
Traceback (most recent call last):
  File "C:\Users\Миша\AppData\Local\Programs\Python\Python313-32\Lib\site-packages\telebot\__init__.py", line 1235, in __threaded_polling
    self.worker_pool.raise_exceptions()
    ~~~~~~~~~~~~~~~~~~~~~~~~~~~~~~~~~^^
  File "C:\Users\Миша\AppData\Local\Programs\Python\Python313-32\Lib\site-packages\telebot\util.py", line 151, in raise_exceptions
    raise self.exception_info
  File "C:\Users\Миша\AppData\Local\Programs\Python\Python313-32\Lib\site-packages\telebot\util.py", line 94, in run
    task(*args, **kwargs)
    ~~~~^^^^^^^^^^^^^^^^^
  File "C:\Users\Миша\AppData\Local\Programs\Python\Python313-32\Lib\site-packages\telebot\__init__.py", line 9854, in _run_middlewares_and_handler
    result = handler['function'](message)
  File "C:\Users\Миша\Desktop\AI assistent\Assistent.py", line 85, in start
    bot.reply_to(
    ~~~~~~~~~~~~^
        message,
        ^^^^^^^^
    ...<7 lines>...
        parse_mode='HTML'
        ^^^^^^^^^^^^^^^^^
    )
    ^
  File "C:\Users\Миша\AppData\Local\Programs\Python\Python313-32\Lib\site-packages\telebot\__init__.py", line 6067, in reply_to
    return self.send_message(message.chat.id, text, reply_parameters=reply_parameters, **kwargs)
           ~~~~~~~~~~~~~~~~~^^^^^^^^^^^^^^^^^^^^^^^^^^^^^^^^^^^^^^^^^^^^^^^^^^^^^^^^^^^^^^^^^^^^
  File "C:\Users\Миша\AppData\Local\Programs\Python\Python313-32\Lib\site-packages\telebot\__init__.py", line 1800, in send_message
    apihelper.send_message(
    ~~~~~~~~~~~~~~~~~~~~~~^
        self.token, chat_id, text,
        ^^^^^^^^^^^^^^^^^^^^^^^^^^
    ...<2 lines>...
        reply_parameters=reply_parameters, link_preview_options=link_preview_options, business_connection_id=business_connection_id,
        ^^^^^^^^^^^^^^^^^^^^^^^^^^^^^^^^^^^^^^^^^^^^^^^^^^^^^^^^^^^^^^^^^^^^^^^^^^^^^^^^^^^^^^^^^^^^^^^^^^^^^^^^^^^^^^^^^^^^^^^^^^^^
        message_effect_id=message_effect_id, allow_paid_broadcast=allow_paid_broadcast))
        ^^^^^^^^^^^^^^^^^^^^^^^^^^^^^^^^^^^^^^^^^^^^^^^^^^^^^^^^^^^^^^^^^^^^^^^^^^^^^^^
  File "C:\Users\Миша\AppData\Local\Programs\Python\Python313-32\Lib\site-packages\telebot\apihelper.py", line 275, in send_message
    return _make_request(token, method_url, params=payload, method='post')
  File "C:\Users\Миша\AppData\Local\Programs\Python\Python313-32\Lib\site-packages\telebot\apihelper.py", line 168, in _make_request
    json_result = _check_result(method_name, result)
  File "C:\Users\Миша\AppData\Local\Programs\Python\Python313-32\Lib\site-packages\telebot\apihelper.py", line 195, in _check_result
    raise ApiTelegramException(method_name, result, result_json)
telebot.apihelper.ApiTelegramException: A request to the Telegram API was unsuccessful. Error code: 400. Description: Bad Request: can't parse entities: Unsupported start tag "описание" at byte offset 293

2025-09-29 10:20:07,632 - __main__ - ERROR - Ошибка в polling: HTTPSConnectionPool(host='api.telegram.org', port=443): Max retries exceeded with url: /bot8155922543:AAHd7BVP8629coKuY9e7MqWdu10DG36yZdg/getUpdates?offset=318268650&timeout=20 (Caused by NameResolutionError("<urllib3.connection.HTTPSConnection object at 0x0450DB30>: Failed to resolve 'api.telegram.org' ([Errno 11001] getaddrinfo failed)"))
2025-09-29 10:20:42,895 - TeleBot - ERROR - Threaded polling exception: A request to the Telegram API was unsuccessful. Error code: 400. Description: Bad Request: can't parse entities: Unsupported start tag "описание" at byte offset 293
2025-09-29 10:20:42,936 - TeleBot - ERROR - Exception traceback:
Traceback (most recent call last):
  File "C:\Users\Миша\AppData\Local\Programs\Python\Python313-32\Lib\site-packages\telebot\__init__.py", line 1235, in __threaded_polling
    self.worker_pool.raise_exceptions()
    ~~~~~~~~~~~~~~~~~~~~~~~~~~~~~~~~~^^
  File "C:\Users\Миша\AppData\Local\Programs\Python\Python313-32\Lib\site-packages\telebot\util.py", line 151, in raise_exceptions
    raise self.exception_info
  File "C:\Users\Миша\AppData\Local\Programs\Python\Python313-32\Lib\site-packages\telebot\util.py", line 94, in run
    task(*args, **kwargs)
    ~~~~^^^^^^^^^^^^^^^^^
  File "C:\Users\Миша\AppData\Local\Programs\Python\Python313-32\Lib\site-packages\telebot\__init__.py", line 9854, in _run_middlewares_and_handler
    result = handler['function'](message)
  File "C:\Users\Миша\Desktop\AI assistent\Assistent.py", line 85, in start
    bot.reply_to(
    ~~~~~~~~~~~~^
        message,
        ^^^^^^^^
    ...<7 lines>...
        parse_mode='HTML'
        ^^^^^^^^^^^^^^^^^
    )
    ^
  File "C:\Users\Миша\AppData\Local\Programs\Python\Python313-32\Lib\site-packages\telebot\__init__.py", line 6067, in reply_to
    return self.send_message(message.chat.id, text, reply_parameters=reply_parameters, **kwargs)
           ~~~~~~~~~~~~~~~~~^^^^^^^^^^^^^^^^^^^^^^^^^^^^^^^^^^^^^^^^^^^^^^^^^^^^^^^^^^^^^^^^^^^^
  File "C:\Users\Миша\AppData\Local\Programs\Python\Python313-32\Lib\site-packages\telebot\__init__.py", line 1800, in send_message
    apihelper.send_message(
    ~~~~~~~~~~~~~~~~~~~~~~^
        self.token, chat_id, text,
        ^^^^^^^^^^^^^^^^^^^^^^^^^^
    ...<2 lines>...
        reply_parameters=reply_parameters, link_preview_options=link_preview_options, business_connection_id=business_connection_id,
        ^^^^^^^^^^^^^^^^^^^^^^^^^^^^^^^^^^^^^^^^^^^^^^^^^^^^^^^^^^^^^^^^^^^^^^^^^^^^^^^^^^^^^^^^^^^^^^^^^^^^^^^^^^^^^^^^^^^^^^^^^^^^
        message_effect_id=message_effect_id, allow_paid_broadcast=allow_paid_broadcast))
        ^^^^^^^^^^^^^^^^^^^^^^^^^^^^^^^^^^^^^^^^^^^^^^^^^^^^^^^^^^^^^^^^^^^^^^^^^^^^^^^
  File "C:\Users\Миша\AppData\Local\Programs\Python\Python313-32\Lib\site-packages\telebot\apihelper.py", line 275, in send_message
    return _make_request(token, method_url, params=payload, method='post')
  File "C:\Users\Миша\AppData\Local\Programs\Python\Python313-32\Lib\site-packages\telebot\apihelper.py", line 168, in _make_request
    json_result = _check_result(method_name, result)
  File "C:\Users\Миша\AppData\Local\Programs\Python\Python313-32\Lib\site-packages\telebot\apihelper.py", line 195, in _check_result
    raise ApiTelegramException(method_name, result, result_json)
telebot.apihelper.ApiTelegramException: A request to the Telegram API was unsuccessful. Error code: 400. Description: Bad Request: can't parse entities: Unsupported start tag "описание" at byte offset 293

